<?xml version="1.0" encoding="utf-8"?>
<!-- =================================================================================== -->
<!-- |    This document was autogenerated by xacro from samxl_irb4600_godel_cell.xacro | -->
<!-- |    EDITING THIS FILE BY HAND IS NOT RECOMMENDED                                 | -->
<!-- =================================================================================== -->
<robot name="samxl_godel_irb4600">
  <!-- Conversion were obtained from http://www.e-paint.co.uk/Lab_values.asp
       unless otherwise stated. -->
  <!-- create link based on visual and collision geometry -->
  <link name="pedestal_base_link">
    <visual>
      <origin rpy="1.57079632679 0 0" xyz="0 0 0"/>
      <geometry>
        <mesh filename="package://samxl_abb_cell_support/meshes/visual/pedestal_visual.dae"/>
      </geometry>
    </visual>
    <collision>
      <origin rpy="1.57079632679 0 0" xyz="0 0 0"/>
      <geometry>
        <mesh filename="package://samxl_abb_cell_support/meshes/collision/pedestal_collision.stl"/>
      </geometry>
    </collision>
  </link>
  <link name="pedestal_robot_link"/>
  <joint name="pedestal_robot_link_to_pedestal_base_link" type="fixed">
    <origin rpy="0 0 0" xyz="0 0 0.900"/>
    <parent link="pedestal_base_link"/>
    <child link="pedestal_robot_link"/>
  </joint>
  <!-- link list -->
  <link name="abb_irb4600_base_link">
    <collision name="collision">
      <geometry>
        <mesh filename="package://abb_irb4600_support/meshes/irb4600_common/collision/base_link.stl"/>
      </geometry>
      <material name="">
        <color rgba="0.9254902 0.9254902 0.9058824 1"/>
      </material>
    </collision>
    <visual name="visual">
      <geometry>
        <mesh filename="package://abb_irb4600_support/meshes/irb4600_common/visual/base_link.dae"/>
      </geometry>
      <material name="">
        <color rgba="0.9254902 0.9254902 0.9058824 1"/>
      </material>
      <material name="yellow">
        <color rgba="1 1 0 1"/>
      </material>
    </visual>
  </link>
  <link name="abb_irb4600_link_1">
    <collision name="collision">
      <geometry>
        <mesh filename="package://abb_irb4600_support/meshes/irb4600_common/collision/link_1.stl"/>
      </geometry>
      <material name="">
        <color rgba="0.9254902 0.9254902 0.9058824 1"/>
      </material>
    </collision>
    <visual name="visual">
      <geometry>
        <mesh filename="package://abb_irb4600_support/meshes/irb4600_common/visual/link_1.dae"/>
      </geometry>
      <material name="">
        <color rgba="0.9254902 0.9254902 0.9058824 1"/>
      </material>
      <material name="yellow"/>
    </visual>
  </link>
  <link name="abb_irb4600_link_2">
    <collision name="collision">
      <geometry>
        <mesh filename="package://abb_irb4600_support/meshes/irb4600_40_255/collision/link_2.stl"/>
      </geometry>
      <material name="">
        <color rgba="0.9254902 0.9254902 0.9058824 1"/>
      </material>
    </collision>
    <visual name="visual">
      <geometry>
        <mesh filename="package://abb_irb4600_support/meshes/irb4600_40_255/visual/link_2.dae"/>
      </geometry>
      <material name="">
        <color rgba="0.9254902 0.9254902 0.9058824 1"/>
      </material>
      <material name="yellow"/>
    </visual>
  </link>
  <link name="abb_irb4600_link_3">
    <collision name="collision">
      <geometry>
        <mesh filename="package://abb_irb4600_support/meshes/irb4600_40_255/collision/link_3.stl"/>
      </geometry>
      <material name="">
        <color rgba="0.9254902 0.9254902 0.9058824 1"/>
      </material>
    </collision>
    <visual name="visual">
      <geometry>
        <mesh filename="package://abb_irb4600_support/meshes/irb4600_40_255/visual/link_3.dae"/>
      </geometry>
      <material name="">
        <color rgba="0.9254902 0.9254902 0.9058824 1"/>
      </material>
      <material name="yellow"/>
    </visual>
  </link>
  <link name="abb_irb4600_link_4">
    <collision name="collision">
      <geometry>
        <mesh filename="package://abb_irb4600_support/meshes/irb4600_40_255/collision/link_4.stl"/>
      </geometry>
      <material name="">
        <color rgba="0.9254902 0.9254902 0.9058824 1"/>
      </material>
    </collision>
    <visual name="visual">
      <geometry>
        <mesh filename="package://abb_irb4600_support/meshes/irb4600_40_255/visual/link_4.dae"/>
      </geometry>
      <material name="">
        <color rgba="0.9254902 0.9254902 0.9058824 1"/>
      </material>
      <material name="yellow"/>
    </visual>
  </link>
  <link name="abb_irb4600_link_5">
    <collision name="collision">
      <geometry>
        <mesh filename="package://abb_irb4600_support/meshes/irb4600_40_255/collision/link_5.stl"/>
      </geometry>
      <material name="">
        <color rgba="0.9254902 0.9254902 0.9058824 1"/>
      </material>
    </collision>
    <visual name="visual">
      <geometry>
        <mesh filename="package://abb_irb4600_support/meshes/irb4600_40_255/visual/link_5.dae"/>
      </geometry>
      <material name="">
        <color rgba="0.9254902 0.9254902 0.9058824 1"/>
      </material>
      <material name="yellow"/>
    </visual>
  </link>
  <link name="abb_irb4600_link_6">
    <collision name="collision">
      <geometry>
        <mesh filename="package://abb_irb4600_support/meshes/irb4600_40_255/collision/link_6.stl"/>
      </geometry>
      <material name="">
        <color rgba="0.9254902 0.9254902 0.9058824 1"/>
      </material>
    </collision>
    <visual name="visual">
      <geometry>
        <mesh filename="package://abb_irb4600_support/meshes/irb4600_40_255/visual/link_6.dae"/>
      </geometry>
      <material name="">
        <color rgba="0.9254902 0.9254902 0.9058824 1"/>
      </material>
      <material name="yellow"/>
    </visual>
  </link>
  <link name="abb_irb4600_tool0"/>
  <!-- end of link list -->
  <!-- joint list -->
  <joint name="abb_irb4600_joint_1" type="revolute">
    <origin rpy="0 0 0" xyz="0 0 0.495"/>
    <axis xyz="0 0 1"/>
    <parent link="abb_irb4600_base_link"/>
    <child link="abb_irb4600_link_1"/>
    <limit effort="0" lower="-3.14159265359" upper="3.14159265359" velocity="3.054"/>
  </joint>
  <joint name="abb_irb4600_joint_2" type="revolute">
    <origin rpy="0 0 0" xyz="0.175 0 0"/>
    <axis xyz="0 1 0"/>
    <parent link="abb_irb4600_link_1"/>
    <child link="abb_irb4600_link_2"/>
    <limit effort="0" lower="-1.57079632679" upper="2.61799387799" velocity="3.054"/>
  </joint>
  <joint name="abb_irb4600_joint_3" type="revolute">
    <origin rpy="0 0 0" xyz="0 0 1.095"/>
    <axis xyz="0 1 0"/>
    <parent link="abb_irb4600_link_2"/>
    <child link="abb_irb4600_link_3"/>
    <limit effort="0" lower="-3.14159265359" upper="1.308996939" velocity="3.054"/>
  </joint>
  <joint name="abb_irb4600_joint_4" type="revolute">
    <origin rpy="0 0 0" xyz="0 0 0.175"/>
    <axis xyz="1 0 0"/>
    <parent link="abb_irb4600_link_3"/>
    <child link="abb_irb4600_link_4"/>
    <limit effort="0" lower="-6.98131700798" upper="6.98131700798" velocity="4.363"/>
  </joint>
  <joint name="abb_irb4600_joint_5" type="revolute">
    <origin rpy="0 0 0" xyz="1.270 0 0 "/>
    <axis xyz="0 1 0"/>
    <parent link="abb_irb4600_link_4"/>
    <child link="abb_irb4600_link_5"/>
    <limit effort="0" lower="-2.18166156499" upper="2.09439510239" velocity="4.363"/>
  </joint>
  <joint name="abb_irb4600_joint_6" type="revolute">
    <origin rpy="0 0 0" xyz="0.135 0 0 "/>
    <axis xyz="1 0 0"/>
    <parent link="abb_irb4600_link_5"/>
    <child link="abb_irb4600_link_6"/>
    <limit effort="0" lower="-6.98131700798" upper="6.98131700798" velocity="6.283"/>
  </joint>
  <joint name="abb_irb4600_joint_6-tool0" type="fixed">
    <parent link="abb_irb4600_link_6"/>
    <child link="abb_irb4600_tool0"/>
    <origin rpy="0 1.57079632679 0" xyz="0 0 0"/>
  </joint>
  <!-- end of joint list -->
  <!-- ROS base_link to ABB World Coordinates transform -->
  <link name="abb_irb4600_base"/>
  <joint name="abb_irb4600_base_link-base" type="fixed">
    <origin rpy="0 0 0" xyz="0 0 0"/>
    <parent link="abb_irb4600_base_link"/>
    <child link="abb_irb4600_base"/>
  </joint>
  <!-- ==== LINKS ==== -->
  <!-- Create a base link + tool0 link for the whole assembly -->
  <link name="ft660_base_link"/>
  <link name="ft660_tool0"/>
  <!-- link for robot side adapter plate -->
  <link name="ft660_robot_adapter">
    <visual>
      <origin rpy="-1.57079632679 0 1.57079632679" xyz="0 0 0.015"/>
      <geometry>
        <mesh filename="package://samxl_abb_cell_support/meshes/visual/ft660_irb4600_robotadapter_visual.dae"/>
      </geometry>
    </visual>
    <collision>
      <origin rpy="-1.57079632679 0 1.57079632679" xyz="0 0 0.015"/>
      <geometry>
        <mesh filename="package://samxl_abb_cell_support/meshes/collision/ft660_irb4600_robotadapter_collision.stl"/>
      </geometry>
    </collision>
  </link>
  <!-- link for sensor side adapter plate -->
  <link name="ft660_sensor_adapter">
    <visual>
      <origin rpy="-1.57079632679 0 0" xyz="0 0 0.010"/>
      <geometry>
        <mesh filename="package://samxl_abb_cell_support/meshes/visual/ft660_irb4600_sensoradapter_visual.dae"/>
      </geometry>
    </visual>
    <collision>
      <origin rpy="-1.57079632679 0 0" xyz="0 0 0.010"/>
      <geometry>
        <mesh filename="package://samxl_abb_cell_support/meshes/collision/ft660_irb4600_sensoradapter_collision.stl"/>
      </geometry>
    </collision>
  </link>
  <!-- link for sensor extension plate -->
  <link name="ft660_sensor_extension">
    <visual>
      <origin rpy="0 0 1.57079632679" xyz="0 0.052 0"/>
      <geometry>
        <mesh filename="package://samxl_abb_cell_support/meshes/visual/ft660_irb4600_extensionplate_visual.dae"/>
      </geometry>
    </visual>
    <collision>
      <origin rpy="0 0 1.57079632679" xyz="0 0.052 0"/>
      <geometry>
        <mesh filename="package://samxl_abb_cell_support/meshes/collision/ft660_irb4600_extensionplate_collision.stl"/>
      </geometry>
    </collision>
  </link>
  <!-- link for ft660 sensor -->
  <link name="ft660_sensor">
    <visual>
      <origin rpy="1.57079632679 0 3.14159265359" xyz="0 0 0.020"/>
      <geometry>
        <mesh filename="package://samxl_abb_cell_support/meshes/visual/ft660_sensor_visual.dae"/>
      </geometry>
    </visual>
    <collision>
      <origin rpy="1.57079632679 0 3.14159265359" xyz="0 0 0.020"/>
      <geometry>
        <mesh filename="package://samxl_abb_cell_support/meshes/collision/ft660_sensor_collision.stl"/>
      </geometry>
    </collision>
  </link>
  <!-- ==== JOINTS ==== -->
  <!-- robot adapter plate to eef assembly base_link -->
  <joint name="ft660_robot_adapter_to_ft660_base_link" type="fixed">
    <origin rpy="0 0 0" xyz="0 0 0"/>
    <parent link="ft660_base_link"/>
    <child link="ft660_robot_adapter"/>
  </joint>
  <!-- sensor adapter plate to robot adapter plate -->
  <joint name="ft660_sensor_adapter_to_ft660_robot_adapter" type="fixed">
    <origin rpy="0 0 0" xyz="0 0 0.015"/>
    <parent link="ft660_robot_adapter"/>
    <child link="ft660_sensor_adapter"/>
  </joint>
  <!-- sensor extension plate to robot adapter plate -->
  <joint name="ft660_sensor_extension_to_ft660_robot_adapter" type="fixed">
    <origin rpy="0 0 0" xyz="0 0 0.015"/>
    <parent link="ft660_robot_adapter"/>
    <child link="ft660_sensor_extension"/>
  </joint>
  <!-- sensor to sensor adapter plate -->
  <joint name="ft660_sensor_to_ft660_sensor_adapter" type="fixed">
    <origin rpy="0 0 0" xyz="0 0 0.010"/>
    <parent link="ft660_sensor_adapter"/>
    <child link="ft660_sensor"/>
  </joint>
  <!-- eef assembly tool0 to eef assembly base_link -->
  <joint name="ft660__to_ft660_base_link" type="fixed">
    <origin rpy="0 0 0" xyz="0 0 0.065"/>
    <parent link="ft660_base_link"/>
    <child link="ft660_tool0"/>
  </joint>
  <!-- Links -->
  <!-- None -->
  <!-- Collision geometry for the back wall -->
  <link name="wall_base_link">
    <visual>
      <!-- Back Wall  -->
      <origin rpy="0 0 0" xyz="-0.005 2.5 2.0"/>
      <geometry>
        <box size="0.01 5.0 4.0"/>
      </geometry>
      <material name="Light-Grey">
        <color rgba="0.55 0.55 0.55 1.0"/>
      </material>
    </visual>
    <collision>
      <!-- Left Fence  -->
      <origin rpy="0 0 0" xyz="2.675 0 2.0"/>
      <geometry>
        <box size="5.35 0.01 4.0"/>
      </geometry>
    </collision>
    <collision>
      <!-- Right Fence  -->
      <origin rpy="0 0 0" xyz="4.25 5.0 1.5"/>
      <geometry>
        <box size="8.5 0.01 3"/>
      </geometry>
    </collision>
    <collision>
      <!-- Back Wall  -->
      <origin rpy="0 0 0" xyz="-0.005 2.5 2.0"/>
      <geometry>
        <box size="0.01 5.0 4.0"/>
      </geometry>
    </collision>
  </link>
  <!-- Collision geometry for cable tray -->
  <link name="wall_cabletray_link">
    <visual>
      <!-- Cable Tray -->
      <origin rpy="0 0 0" xyz="0.16 2.5 0.075"/>
      <geometry>
        <box size="0.32 5.0 0.15"/>
      </geometry>
      <material name="Light-Grey">
        <color rgba="0.55 0.55 0.55 1.0"/>
      </material>
    </visual>
    <visual>
      <!-- UTP Box -->
      <origin rpy="0 0 0" xyz="0.26 3.105 0.22"/>
      <geometry>
        <box size="0.22 0.15 0.14"/>
      </geometry>
      <material name="Light-Grey">
        <color rgba="0.55 0.55 0.55 1.0"/>
      </material>
    </visual>
    <collision>
      <!-- Cable Tray -->
      <origin rpy="0 0 0" xyz="0.16 2.5 0.075"/>
      <geometry>
        <box size="0.32 5.0 0.15"/>
      </geometry>
    </collision>
    <collision>
      <!-- UTP Box -->
      <origin rpy="0 0 0" xyz="0.185 3.105 0.22"/>
      <geometry>
        <box size="0.37 0.15 0.14"/>
      </geometry>
    </collision>
  </link>
  <!-- Collision geometry for fire-hose -->
  <link name="wall_firehose_link">
    <visual>
      <!-- Hose Reel -->
      <origin rpy="0 1.57079632679 0" xyz="0.125 0 0"/>
      <geometry>
        <cylinder length="0.25" radius="0.25"/>
      </geometry>
      <material name="red">
        <color rgba="0.4 0 0 1.0"/>
      </material>
    </visual>
    <visual>
      <!-- Pipe -->
      <origin rpy="0 0 0" xyz="0.05 0 1.32"/>
      <geometry>
        <box size="0.1 0.1 2.64"/>
      </geometry>
      <material name="red">
        <color rgba="0.4 0 0 1.0"/>
      </material>
    </visual>
    <collision>
      <!-- Hose Reel -->
      <origin rpy="0 1.57079632679 0" xyz="0.1375 0 0"/>
      <geometry>
        <cylinder length="0.275" radius="0.275"/>
      </geometry>
    </collision>
    <collision>
      <!-- Hose Bracket and hose itself -->
      <origin rpy="0 1.57079632679 0" xyz="0.075 0 0"/>
      <geometry>
        <cylinder length="0.15" radius="0.5"/>
      </geometry>
    </collision>
    <collision>
      <!-- Pipe Valve -->
      <origin rpy="0 0 0" xyz="0.05 0 0.32"/>
      <geometry>
        <box size="0.1 0.2 0.64"/>
      </geometry>
    </collision>
    <collision>
      <!-- Pipe -->
      <origin rpy="0 0 0" xyz="0.05 0 1.32"/>
      <geometry>
        <box size="0.1 0.1 2.64"/>
      </geometry>
    </collision>
  </link>
  <!-- Joints -->
  <!-- Wall to wall-mounted cable tray -->
  <joint name="wall_base_link_to_wall_cabletray_link" type="fixed">
    <origin rpy="0 0 0" xyz="0 0 2.0"/>
    <parent link="wall_base_link"/>
    <child link="wall_cabletray_link"/>
  </joint>
  <!-- Wall to fire-hose -->
  <joint name="wall_base_link_to_wall_firehose_link" type="fixed">
    <origin rpy="0 0 0" xyz="0 1.375 1.360"/>
    <parent link="wall_base_link"/>
    <child link="wall_firehose_link"/>
  </joint>
  <!-- Collision geometry for left-table -->
  <link name="left_table_base_link">
    <visual>
      <origin rpy="0 0 0" xyz="0 0 0.35"/>
      <geometry>
        <box size="2.0 1.2 0.7"/>
      </geometry>
      <material name="Dark-Grey">
        <color rgba="0.15 0.15 0.15 1.0"/>
      </material>
    </visual>
    <collision>
      <origin rpy="0 0 0" xyz="0 0 0.35"/>
      <geometry>
        <box size="2.0 1.2 0.7"/>
      </geometry>
    </collision>
  </link>
  <!-- JOINTS -->
  <!-- Robot to Pedestal -->
  <joint name="abb_irb4600_base_link_to_pedestal_robot_link" type="fixed">
    <origin rpy="0 0 0" xyz="0 0 0"/>
    <parent link="pedestal_robot_link"/>
    <child link="abb_irb4600_base_link"/>
  </joint>
  <!-- Wall to Pedestal -->
  <joint name="wall_base_link_to_pedestal_base_link" type="fixed">
    <origin rpy="0 0 0" xyz="-1.950 -2.505 0"/>
    <parent link="pedestal_base_link"/>
    <child link="wall_base_link"/>
  </joint>
  <!-- Left Table to Pedestal -->
  <joint name="left_table_base_link_to_pedestal_base_link" type="fixed">
    <origin rpy="0 0 0" xyz="0 -1.405 0"/>
    <parent link="pedestal_base_link"/>
    <child link="left_table_base_link"/>
  </joint>
  <!-- FT660 Sensor to Robot -->
  <joint name="ft660_robotadapter_base_link_to_abb_irb4600_tool0" type="fixed">
    <origin rpy="0 0 0" xyz="0 0 0"/>
    <parent link="abb_irb4600_tool0"/>
    <child link="ft660_base_link"/>
  </joint>
  <!-- IGUS Dresspack to Robot -->
  <!-- <joint name="${prefix}dresspack_bracket_to_${prefix}abb_irb4600_link_4" type="fixed">
            <origin xyz="-0.43 -0.095 0.095" rpy="${pi/2} 0 0"/>
            <parent link="${prefix}abb_irb4600_link_4"/>
            <child link="${prefix}dresspack_base_link"/>
        </joint> -->
  <!-- Links -->
  <link name="thorlabs_base_link">
    <!-- Visuals -->
    <visual>
      <!-- Adapter Plate  -->
      <origin rpy="0 0 0" xyz="0 0 0.00635"/>
      <geometry>
        <box size="0.1125 0.1125 0.0127"/>
      </geometry>
      <material name="aluminium">
        <color rgba="0.825 0.825 0.825 1"/>
      </material>
    </visual>
    <visual>
      <!-- Thorlaps Plate -->
      <origin rpy="0 0 0" xyz="0 0 0.0127"/>
      <geometry>
        <mesh filename="package://samxl_abb_cell_support/meshes/visual/thorlabs_plate.stl"/>
      </geometry>
      <material name="thorlabs_black">
        <color rgba="0.25 0.25 0.25 1"/>
      </material>
    </visual>
    <!-- Collisions -->
    <collision>
      <!-- Adapter Plate  -->
      <origin rpy="0 0 0" xyz="0 0 0.00635"/>
      <geometry>
        <box size="0.1125 0.1125 0.0127"/>
      </geometry>
    </collision>
    <collision>
      <!-- Thorlaps Plate -->
      <origin rpy="0 0 0" xyz="0 0 0.01905"/>
      <geometry>
        <box size="0.1125 0.1125 0.0127"/>
      </geometry>
    </collision>
  </link>
  <link name="thorlabs_tool0"/>
  <!-- Joints -->
  <!-- Wall to wall-mounted cable tray -->
  <joint name="thorlabs_base_link_to_thorlabs_tool0" type="fixed">
    <origin rpy="0 0 0" xyz="0 0 0.0254"/>
    <parent link="thorlabs_base_link"/>
    <child link="thorlabs_tool0"/>
  </joint>
  <!-- Links -->
  <link name="godel_eef_base_link">
    <visual>
      <origin rpy="0 0 0" xyz="0 0 0"/>
      <geometry>
        <mesh filename="package://samxl_godel_irb4600_support/meshes/visual/godel_eef_with_sensors.stl"/>
      </geometry>
      <material name="eef_blue">
        <color rgba="0.1 0.7 0.7 1"/>
      </material>
    </visual>
    <!-- <collision> -->
    <!-- <origin xyz="0 0 0" rpy"0 0 0"/> -->
    <!-- <mesh filename="package://samxl_godel_irb4600_support/meshes/collision/.stl" /> -->
    <!-- </collision> -->
  </link>
  <link name="godel_eef_zivid_tool_frame"/>
  <link name="godel_eef_blender_tool_frame"/>
  <link name="godel_eef_scancontrol_tool_frame"/>
  <link name="godel_eef_ensenso_tool_frame"/>
  <!-- Joints -->
  <joint name="godel_eef_base_link_to_godel_eef_zivid_tool_frame" type="fixed">
    <origin rpy="0 0 0" xyz="0 0 0"/>
    <parent link="godel_eef_base_link"/>
    <child link="godel_eef_zivid_tool_frame"/>
  </joint>
  <joint name="godel_eef_base_link_to_godel_eef_blender_tool_frame" type="fixed">
    <origin rpy="0 0 0" xyz="0 0 0"/>
    <parent link="godel_eef_base_link"/>
    <child link="godel_eef_blender_tool_frame"/>
  </joint>
  <joint name="godel_eef_base_link_to_godel_eef_scancontrol_tool_frame" type="fixed">
    <origin rpy="0 0 0" xyz="0 0 0"/>
    <parent link="godel_eef_base_link"/>
    <child link="godel_eef_scancontrol_tool_frame"/>
  </joint>
  <joint name="godel_eef_base_link_to_godel_eef_ensenso_tool_frame" type="fixed">
    <origin rpy="0 0 0" xyz="0 0 0"/>
    <parent link="godel_eef_base_link"/>
    <child link="godel_eef_ensenso_tool_frame"/>
  </joint>
  <link name="world_frame"/>
  <!-- Joints -->
  <joint name="world_to_pedestal_base_link" type="fixed">
    <parent link="world_frame"/>
    <child link="pedestal_base_link"/>
    <origin rpy="0 0 0" xyz="0 0 0"/>
  </joint>
  <joint name="ft660_tool0_to_thorlabs_base_link" type="fixed">
    <origin rpy="0 0 0" xyz="0 0 0"/>
    <parent link="ft660_tool0"/>
    <child link="thorlabs_base_link"/>
  </joint>
  <joint name="thorlabs_tool0_to_godel_eef_base_link" type="fixed">
    <origin rpy="0 0 0" xyz="0 0 0"/>
    <parent link="thorlabs_tool0"/>
    <child link="godel_eef_base_link"/>
  </joint>
</robot>
